Exception on /ask [GET]
Traceback (most recent call last):
  File "D:\devuri\workspace\server\venv352\lib\site-packages\flask\app.py", line 2292, in wsgi_app
    response = self.full_dispatch_request()
  File "D:\devuri\workspace\server\venv352\lib\site-packages\flask\app.py", line 1815, in full_dispatch_request
    rv = self.handle_user_exception(e)
  File "D:\devuri\workspace\server\venv352\lib\site-packages\flask\app.py", line 1718, in handle_user_exception
    reraise(exc_type, exc_value, tb)
  File "D:\devuri\workspace\server\venv352\lib\site-packages\flask\_compat.py", line 35, in reraise
    raise value
  File "D:\devuri\workspace\server\venv352\lib\site-packages\flask\app.py", line 1813, in full_dispatch_request
    rv = self.dispatch_request()
  File "D:\devuri\workspace\server\venv352\lib\site-packages\flask\app.py", line 1799, in dispatch_request
    return self.view_functions[rule.endpoint](**req.view_args)
  File "D:\devuri\workspace\server\DajeongBot-server\djbot\blueprints\test.py", line 149, in ask
    "id": account['id'],
TypeError: 'Account' object is not subscriptable
Exception on /messages/ [POST]
Traceback (most recent call last):
  File "D:\devuri\workspace\server\venv352\lib\site-packages\flask\app.py", line 2292, in wsgi_app
    response = self.full_dispatch_request()
  File "D:\devuri\workspace\server\venv352\lib\site-packages\flask\app.py", line 1815, in full_dispatch_request
    rv = self.handle_user_exception(e)
  File "D:\devuri\workspace\server\venv352\lib\site-packages\flask\app.py", line 1718, in handle_user_exception
    reraise(exc_type, exc_value, tb)
  File "D:\devuri\workspace\server\venv352\lib\site-packages\flask\_compat.py", line 35, in reraise
    raise value
  File "D:\devuri\workspace\server\venv352\lib\site-packages\flask\app.py", line 1813, in full_dispatch_request
    rv = self.dispatch_request()
  File "D:\devuri\workspace\server\venv352\lib\site-packages\flask\app.py", line 1799, in dispatch_request
    return self.view_functions[rule.endpoint](**req.view_args)
  File "D:\devuri\workspace\server\DajeongBot-server\djbot\blueprints\message.py", line 35, in add_messages
    result = reply_message(content)
  File "D:\devuri\workspace\server\DajeongBot-server\djbot\blueprints\message.py", line 137, in reply_message
    insert_message_multiple(content['account_id'], result_json['result']['content'], result['result']['time'])
KeyError: 'result'
Exception on /messages/ [POST]
Traceback (most recent call last):
  File "D:\devuri\workspace\server\venv352\lib\site-packages\flask\app.py", line 2292, in wsgi_app
    response = self.full_dispatch_request()
  File "D:\devuri\workspace\server\venv352\lib\site-packages\flask\app.py", line 1815, in full_dispatch_request
    rv = self.handle_user_exception(e)
  File "D:\devuri\workspace\server\venv352\lib\site-packages\flask\app.py", line 1718, in handle_user_exception
    reraise(exc_type, exc_value, tb)
  File "D:\devuri\workspace\server\venv352\lib\site-packages\flask\_compat.py", line 35, in reraise
    raise value
  File "D:\devuri\workspace\server\venv352\lib\site-packages\flask\app.py", line 1813, in full_dispatch_request
    rv = self.dispatch_request()
  File "D:\devuri\workspace\server\venv352\lib\site-packages\flask\app.py", line 1799, in dispatch_request
    return self.view_functions[rule.endpoint](**req.view_args)
  File "D:\devuri\workspace\server\DajeongBot-server\djbot\blueprints\message.py", line 35, in add_messages
    result = reply_message(content)
  File "D:\devuri\workspace\server\DajeongBot-server\djbot\blueprints\message.py", line 137, in reply_message
    insert_message_multiple(content['account_id'], result_json['result']['content'], result_json['result']['time'])
  File "D:\devuri\workspace\server\DajeongBot-server\djbot\blueprints\message.py", line 324, in insert_message_multiple
    for message in content['content']:
TypeError: list indices must be integers or slices, not str
Exception on /messages/ [POST]
Traceback (most recent call last):
  File "D:\devuri\workspace\server\venv352\lib\site-packages\flask\app.py", line 2292, in wsgi_app
    response = self.full_dispatch_request()
  File "D:\devuri\workspace\server\venv352\lib\site-packages\flask\app.py", line 1815, in full_dispatch_request
    rv = self.handle_user_exception(e)
  File "D:\devuri\workspace\server\venv352\lib\site-packages\flask\app.py", line 1718, in handle_user_exception
    reraise(exc_type, exc_value, tb)
  File "D:\devuri\workspace\server\venv352\lib\site-packages\flask\_compat.py", line 35, in reraise
    raise value
  File "D:\devuri\workspace\server\venv352\lib\site-packages\flask\app.py", line 1813, in full_dispatch_request
    rv = self.dispatch_request()
  File "D:\devuri\workspace\server\venv352\lib\site-packages\flask\app.py", line 1799, in dispatch_request
    return self.view_functions[rule.endpoint](**req.view_args)
  File "D:\devuri\workspace\server\DajeongBot-server\djbot\blueprints\message.py", line 35, in add_messages
    result = reply_message(content)
  File "D:\devuri\workspace\server\DajeongBot-server\djbot\blueprints\message.py", line 137, in reply_message
    insert_message_multiple(content['account_id'], result_json['result'], result_json['result']['time'])
  File "D:\devuri\workspace\server\DajeongBot-server\djbot\blueprints\message.py", line 325, in insert_message_multiple
    insert_messages_single(account_id, message, content['node_type'], content['chat_type'], timestamp)
  File "D:\devuri\workspace\server\DajeongBot-server\djbot\blueprints\message.py", line 329, in insert_messages_single
    chat = Chat(account_id=account_id, content=message, node_tye=node_tye, chat_type=chat_type, time=timestamp, isBot=1)
  File "<string>", line 4, in __init__
  File "D:\devuri\workspace\server\venv352\lib\site-packages\sqlalchemy\orm\state.py", line 417, in _initialize_instance
    manager.dispatch.init_failure(self, args, kwargs)
  File "D:\devuri\workspace\server\venv352\lib\site-packages\sqlalchemy\util\langhelpers.py", line 66, in __exit__
    compat.reraise(exc_type, exc_value, exc_tb)
  File "D:\devuri\workspace\server\venv352\lib\site-packages\sqlalchemy\util\compat.py", line 249, in reraise
    raise value
  File "D:\devuri\workspace\server\venv352\lib\site-packages\sqlalchemy\orm\state.py", line 414, in _initialize_instance
    return manager.original_init(*mixed[1:], **kwargs)
  File "D:\devuri\workspace\server\venv352\lib\site-packages\sqlalchemy\ext\declarative\base.py", line 699, in _declarative_constructor
    (k, cls_.__name__))
TypeError: 'node_tye' is an invalid keyword argument for Chat
Exception on /messages/ [POST]
Traceback (most recent call last):
  File "D:\devuri\workspace\server\venv352\lib\site-packages\flask\app.py", line 2292, in wsgi_app
    response = self.full_dispatch_request()
  File "D:\devuri\workspace\server\venv352\lib\site-packages\flask\app.py", line 1815, in full_dispatch_request
    rv = self.handle_user_exception(e)
  File "D:\devuri\workspace\server\venv352\lib\site-packages\flask\app.py", line 1718, in handle_user_exception
    reraise(exc_type, exc_value, tb)
  File "D:\devuri\workspace\server\venv352\lib\site-packages\flask\_compat.py", line 35, in reraise
    raise value
  File "D:\devuri\workspace\server\venv352\lib\site-packages\flask\app.py", line 1813, in full_dispatch_request
    rv = self.dispatch_request()
  File "D:\devuri\workspace\server\venv352\lib\site-packages\flask\app.py", line 1799, in dispatch_request
    return self.view_functions[rule.endpoint](**req.view_args)
  File "D:\devuri\workspace\server\DajeongBot-server\djbot\blueprints\message.py", line 39, in add_messages
    result = reply_message_for_select_review(content, contents['response']['select_idx'])
TypeError: list indices must be integers or slices, not str
Exception on /messages/ [POST]
Traceback (most recent call last):
  File "D:\devuri\workspace\server\venv352\lib\site-packages\flask\app.py", line 2292, in wsgi_app
    response = self.full_dispatch_request()
  File "D:\devuri\workspace\server\venv352\lib\site-packages\flask\app.py", line 1815, in full_dispatch_request
    rv = self.handle_user_exception(e)
  File "D:\devuri\workspace\server\venv352\lib\site-packages\flask\app.py", line 1718, in handle_user_exception
    reraise(exc_type, exc_value, tb)
  File "D:\devuri\workspace\server\venv352\lib\site-packages\flask\_compat.py", line 35, in reraise
    raise value
  File "D:\devuri\workspace\server\venv352\lib\site-packages\flask\app.py", line 1813, in full_dispatch_request
    rv = self.dispatch_request()
  File "D:\devuri\workspace\server\venv352\lib\site-packages\flask\app.py", line 1799, in dispatch_request
    return self.view_functions[rule.endpoint](**req.view_args)
  File "D:\devuri\workspace\server\DajeongBot-server\djbot\blueprints\message.py", line 39, in add_messages
    result = reply_message_for_select_review(content, contents['response']['select_idx'])
TypeError: list indices must be integers or slices, not str
