Exception on /events/dates/32 [GET]
Traceback (most recent call last):
  File "D:\devuri\workspace\server\venv352\lib\site-packages\sqlalchemy\engine\base.py", line 2158, in _wrap_pool_connect
    return fn()
  File "D:\devuri\workspace\server\venv352\lib\site-packages\sqlalchemy\pool.py", line 403, in connect
    return _ConnectionFairy._checkout(self)
  File "D:\devuri\workspace\server\venv352\lib\site-packages\sqlalchemy\pool.py", line 791, in _checkout
    fairy = _ConnectionRecord.checkout(pool)
  File "D:\devuri\workspace\server\venv352\lib\site-packages\sqlalchemy\pool.py", line 537, in checkout
    rec._checkin_failed(err)
  File "D:\devuri\workspace\server\venv352\lib\site-packages\sqlalchemy\util\langhelpers.py", line 66, in __exit__
    compat.reraise(exc_type, exc_value, exc_tb)
  File "D:\devuri\workspace\server\venv352\lib\site-packages\sqlalchemy\util\compat.py", line 249, in reraise
    raise value
  File "D:\devuri\workspace\server\venv352\lib\site-packages\sqlalchemy\pool.py", line 534, in checkout
    dbapi_connection = rec.get_connection()
  File "D:\devuri\workspace\server\venv352\lib\site-packages\sqlalchemy\pool.py", line 630, in get_connection
    self.__connect()
  File "D:\devuri\workspace\server\venv352\lib\site-packages\sqlalchemy\pool.py", line 674, in __connect
    connection = pool._invoke_creator(self)
  File "D:\devuri\workspace\server\venv352\lib\site-packages\sqlalchemy\engine\strategies.py", line 106, in connect
    return dialect.connect(*cargs, **cparams)
  File "D:\devuri\workspace\server\venv352\lib\site-packages\sqlalchemy\engine\default.py", line 412, in connect
    return self.dbapi.connect(*cargs, **cparams)
  File "D:\devuri\workspace\server\venv352\lib\site-packages\MySQLdb\__init__.py", line 86, in Connect
    return Connection(*args, **kwargs)
  File "D:\devuri\workspace\server\venv352\lib\site-packages\MySQLdb\connections.py", line 204, in __init__
    super(Connection, self).__init__(*args, **kwargs2)
_mysql_exceptions.OperationalError: (2003, "Can't connect to MySQL server on '119.205.221.104' (10060)")

The above exception was the direct cause of the following exception:

Traceback (most recent call last):
  File "D:\devuri\workspace\server\venv352\lib\site-packages\flask\app.py", line 2292, in wsgi_app
    response = self.full_dispatch_request()
  File "D:\devuri\workspace\server\venv352\lib\site-packages\flask\app.py", line 1815, in full_dispatch_request
    rv = self.handle_user_exception(e)
  File "D:\devuri\workspace\server\venv352\lib\site-packages\flask\app.py", line 1718, in handle_user_exception
    reraise(exc_type, exc_value, tb)
  File "D:\devuri\workspace\server\venv352\lib\site-packages\flask\_compat.py", line 35, in reraise
    raise value
  File "D:\devuri\workspace\server\venv352\lib\site-packages\flask\app.py", line 1813, in full_dispatch_request
    rv = self.dispatch_request()
  File "D:\devuri\workspace\server\venv352\lib\site-packages\flask\app.py", line 1799, in dispatch_request
    return self.view_functions[rule.endpoint](**req.view_args)
  File "D:\devuri\workspace\server\DajeongBot-server\djbot\blueprints\event.py", line 9, in get_dates_having_event
    events = Event.query.filter(Event.account_id == account_id).order_by(Event.id)
  File "D:\devuri\workspace\server\venv352\lib\site-packages\sqlalchemy\orm\query.py", line 2988, in __iter__
    return self._execute_and_instances(context)
  File "D:\devuri\workspace\server\venv352\lib\site-packages\sqlalchemy\orm\query.py", line 3009, in _execute_and_instances
    close_with_result=True)
  File "D:\devuri\workspace\server\venv352\lib\site-packages\sqlalchemy\orm\query.py", line 3018, in _get_bind_args
    **kw
  File "D:\devuri\workspace\server\venv352\lib\site-packages\sqlalchemy\orm\query.py", line 3000, in _connection_from_session
    conn = self.session.connection(**kw)
  File "D:\devuri\workspace\server\venv352\lib\site-packages\sqlalchemy\orm\session.py", line 1035, in connection
    execution_options=execution_options)
  File "D:\devuri\workspace\server\venv352\lib\site-packages\sqlalchemy\orm\session.py", line 1040, in _connection_for_bind
    engine, execution_options)
  File "D:\devuri\workspace\server\venv352\lib\site-packages\sqlalchemy\orm\session.py", line 409, in _connection_for_bind
    conn = bind.contextual_connect()
  File "D:\devuri\workspace\server\venv352\lib\site-packages\sqlalchemy\engine\base.py", line 2123, in contextual_connect
    self._wrap_pool_connect(self.pool.connect, None),
  File "D:\devuri\workspace\server\venv352\lib\site-packages\sqlalchemy\engine\base.py", line 2162, in _wrap_pool_connect
    e, dialect, self)
  File "D:\devuri\workspace\server\venv352\lib\site-packages\sqlalchemy\engine\base.py", line 1476, in _handle_dbapi_exception_noconnection
    exc_info
  File "D:\devuri\workspace\server\venv352\lib\site-packages\sqlalchemy\util\compat.py", line 265, in raise_from_cause
    reraise(type(exception), exception, tb=exc_tb, cause=cause)
  File "D:\devuri\workspace\server\venv352\lib\site-packages\sqlalchemy\util\compat.py", line 248, in reraise
    raise value.with_traceback(tb)
  File "D:\devuri\workspace\server\venv352\lib\site-packages\sqlalchemy\engine\base.py", line 2158, in _wrap_pool_connect
    return fn()
  File "D:\devuri\workspace\server\venv352\lib\site-packages\sqlalchemy\pool.py", line 403, in connect
    return _ConnectionFairy._checkout(self)
  File "D:\devuri\workspace\server\venv352\lib\site-packages\sqlalchemy\pool.py", line 791, in _checkout
    fairy = _ConnectionRecord.checkout(pool)
  File "D:\devuri\workspace\server\venv352\lib\site-packages\sqlalchemy\pool.py", line 537, in checkout
    rec._checkin_failed(err)
  File "D:\devuri\workspace\server\venv352\lib\site-packages\sqlalchemy\util\langhelpers.py", line 66, in __exit__
    compat.reraise(exc_type, exc_value, exc_tb)
  File "D:\devuri\workspace\server\venv352\lib\site-packages\sqlalchemy\util\compat.py", line 249, in reraise
    raise value
  File "D:\devuri\workspace\server\venv352\lib\site-packages\sqlalchemy\pool.py", line 534, in checkout
    dbapi_connection = rec.get_connection()
  File "D:\devuri\workspace\server\venv352\lib\site-packages\sqlalchemy\pool.py", line 630, in get_connection
    self.__connect()
  File "D:\devuri\workspace\server\venv352\lib\site-packages\sqlalchemy\pool.py", line 674, in __connect
    connection = pool._invoke_creator(self)
  File "D:\devuri\workspace\server\venv352\lib\site-packages\sqlalchemy\engine\strategies.py", line 106, in connect
    return dialect.connect(*cargs, **cparams)
  File "D:\devuri\workspace\server\venv352\lib\site-packages\sqlalchemy\engine\default.py", line 412, in connect
    return self.dbapi.connect(*cargs, **cparams)
  File "D:\devuri\workspace\server\venv352\lib\site-packages\MySQLdb\__init__.py", line 86, in Connect
    return Connection(*args, **kwargs)
  File "D:\devuri\workspace\server\venv352\lib\site-packages\MySQLdb\connections.py", line 204, in __init__
    super(Connection, self).__init__(*args, **kwargs2)
sqlalchemy.exc.OperationalError: (_mysql_exceptions.OperationalError) (2003, "Can't connect to MySQL server on '119.205.221.104' (10060)") (Background on this error at: http://sqlalche.me/e/e3q8)
Exception on /messages/ [POST]
Traceback (most recent call last):
  File "D:\devuri\workspace\server\venv352\lib\site-packages\flask\app.py", line 2292, in wsgi_app
    response = self.full_dispatch_request()
  File "D:\devuri\workspace\server\venv352\lib\site-packages\flask\app.py", line 1815, in full_dispatch_request
    rv = self.handle_user_exception(e)
  File "D:\devuri\workspace\server\venv352\lib\site-packages\flask\app.py", line 1718, in handle_user_exception
    reraise(exc_type, exc_value, tb)
  File "D:\devuri\workspace\server\venv352\lib\site-packages\flask\_compat.py", line 35, in reraise
    raise value
  File "D:\devuri\workspace\server\venv352\lib\site-packages\flask\app.py", line 1813, in full_dispatch_request
    rv = self.dispatch_request()
  File "D:\devuri\workspace\server\venv352\lib\site-packages\flask\app.py", line 1799, in dispatch_request
    return self.view_functions[rule.endpoint](**req.view_args)
  File "D:\devuri\workspace\server\DajeongBot-server\djbot\blueprints\message.py", line 28, in add_messages
    result = reply_message(content)
  File "D:\devuri\workspace\server\DajeongBot-server\djbot\blueprints\message.py", line 61, in reply_message
    when = current + datetime.timedelta(days=param['where'])
TypeError: unsupported type for timedelta days component: str
Exception on /messages/ [POST]
Traceback (most recent call last):
  File "D:\devuri\workspace\server\venv352\lib\site-packages\flask\app.py", line 2292, in wsgi_app
    response = self.full_dispatch_request()
  File "D:\devuri\workspace\server\venv352\lib\site-packages\flask\app.py", line 1815, in full_dispatch_request
    rv = self.handle_user_exception(e)
  File "D:\devuri\workspace\server\venv352\lib\site-packages\flask\app.py", line 1718, in handle_user_exception
    reraise(exc_type, exc_value, tb)
  File "D:\devuri\workspace\server\venv352\lib\site-packages\flask\_compat.py", line 35, in reraise
    raise value
  File "D:\devuri\workspace\server\venv352\lib\site-packages\flask\app.py", line 1813, in full_dispatch_request
    rv = self.dispatch_request()
  File "D:\devuri\workspace\server\venv352\lib\site-packages\flask\app.py", line 1799, in dispatch_request
    return self.view_functions[rule.endpoint](**req.view_args)
  File "D:\devuri\workspace\server\DajeongBot-server\djbot\blueprints\message.py", line 28, in add_messages
    result = reply_message(content)
  File "D:\devuri\workspace\server\DajeongBot-server\djbot\blueprints\message.py", line 61, in reply_message
    when = current + datetime.timedelta(days=param['when'])
TypeError: unsupported type for timedelta days component: str
