Exception on /users/signup [POST]
Traceback (most recent call last):
  File "D:\devuri\workspace\server\venv352\lib\site-packages\sqlalchemy\engine\base.py", line 1193, in _execute_context
    context)
  File "D:\devuri\workspace\server\venv352\lib\site-packages\sqlalchemy\engine\default.py", line 509, in do_execute
    cursor.execute(statement, parameters)
  File "D:\devuri\workspace\server\venv352\lib\site-packages\MySQLdb\cursors.py", line 250, in execute
    self.errorhandler(self, exc, value)
  File "D:\devuri\workspace\server\venv352\lib\site-packages\MySQLdb\connections.py", line 50, in defaulterrorhandler
    raise errorvalue
  File "D:\devuri\workspace\server\venv352\lib\site-packages\MySQLdb\cursors.py", line 247, in execute
    res = self._query(query)
  File "D:\devuri\workspace\server\venv352\lib\site-packages\MySQLdb\cursors.py", line 411, in _query
    rowcount = self._do_query(q)
  File "D:\devuri\workspace\server\venv352\lib\site-packages\MySQLdb\cursors.py", line 374, in _do_query
    db.query(q)
  File "D:\devuri\workspace\server\venv352\lib\site-packages\MySQLdb\connections.py", line 277, in query
    _mysql.connection.query(self, query)
_mysql_exceptions.OperationalError: (1292, "Incorrect date value: '200159' for column 'birthday' at row 1")

The above exception was the direct cause of the following exception:

Traceback (most recent call last):
  File "D:\devuri\workspace\server\venv352\lib\site-packages\flask\app.py", line 2292, in wsgi_app
    response = self.full_dispatch_request()
  File "D:\devuri\workspace\server\venv352\lib\site-packages\flask\app.py", line 1815, in full_dispatch_request
    rv = self.handle_user_exception(e)
  File "D:\devuri\workspace\server\venv352\lib\site-packages\flask\app.py", line 1718, in handle_user_exception
    reraise(exc_type, exc_value, tb)
  File "D:\devuri\workspace\server\venv352\lib\site-packages\flask\_compat.py", line 35, in reraise
    raise value
  File "D:\devuri\workspace\server\venv352\lib\site-packages\flask\app.py", line 1813, in full_dispatch_request
    rv = self.dispatch_request()
  File "D:\devuri\workspace\server\venv352\lib\site-packages\flask\app.py", line 1799, in dispatch_request
    return self.view_functions[rule.endpoint](**req.view_args)
  File "D:\devuri\workspace\server\DajeongBot-server\djbot\blueprints\user.py", line 92, in signup
    db.session.commit()
  File "D:\devuri\workspace\server\venv352\lib\site-packages\sqlalchemy\orm\scoping.py", line 153, in do
    return getattr(self.registry(), name)(*args, **kwargs)
  File "D:\devuri\workspace\server\venv352\lib\site-packages\sqlalchemy\orm\session.py", line 943, in commit
    self.transaction.commit()
  File "D:\devuri\workspace\server\venv352\lib\site-packages\sqlalchemy\orm\session.py", line 467, in commit
    self._prepare_impl()
  File "D:\devuri\workspace\server\venv352\lib\site-packages\sqlalchemy\orm\session.py", line 447, in _prepare_impl
    self.session.flush()
  File "D:\devuri\workspace\server\venv352\lib\site-packages\sqlalchemy\orm\session.py", line 2254, in flush
    self._flush(objects)
  File "D:\devuri\workspace\server\venv352\lib\site-packages\sqlalchemy\orm\session.py", line 2380, in _flush
    transaction.rollback(_capture_exception=True)
  File "D:\devuri\workspace\server\venv352\lib\site-packages\sqlalchemy\util\langhelpers.py", line 66, in __exit__
    compat.reraise(exc_type, exc_value, exc_tb)
  File "D:\devuri\workspace\server\venv352\lib\site-packages\sqlalchemy\util\compat.py", line 249, in reraise
    raise value
  File "D:\devuri\workspace\server\venv352\lib\site-packages\sqlalchemy\orm\session.py", line 2344, in _flush
    flush_context.execute()
  File "D:\devuri\workspace\server\venv352\lib\site-packages\sqlalchemy\orm\unitofwork.py", line 391, in execute
    rec.execute(self)
  File "D:\devuri\workspace\server\venv352\lib\site-packages\sqlalchemy\orm\unitofwork.py", line 556, in execute
    uow
  File "D:\devuri\workspace\server\venv352\lib\site-packages\sqlalchemy\orm\persistence.py", line 181, in save_obj
    mapper, table, insert)
  File "D:\devuri\workspace\server\venv352\lib\site-packages\sqlalchemy\orm\persistence.py", line 866, in _emit_insert_statements
    execute(statement, params)
  File "D:\devuri\workspace\server\venv352\lib\site-packages\sqlalchemy\engine\base.py", line 948, in execute
    return meth(self, multiparams, params)
  File "D:\devuri\workspace\server\venv352\lib\site-packages\sqlalchemy\sql\elements.py", line 269, in _execute_on_connection
    return connection._execute_clauseelement(self, multiparams, params)
  File "D:\devuri\workspace\server\venv352\lib\site-packages\sqlalchemy\engine\base.py", line 1060, in _execute_clauseelement
    compiled_sql, distilled_params
  File "D:\devuri\workspace\server\venv352\lib\site-packages\sqlalchemy\engine\base.py", line 1200, in _execute_context
    context)
  File "D:\devuri\workspace\server\venv352\lib\site-packages\sqlalchemy\engine\base.py", line 1413, in _handle_dbapi_exception
    exc_info
  File "D:\devuri\workspace\server\venv352\lib\site-packages\sqlalchemy\util\compat.py", line 265, in raise_from_cause
    reraise(type(exception), exception, tb=exc_tb, cause=cause)
  File "D:\devuri\workspace\server\venv352\lib\site-packages\sqlalchemy\util\compat.py", line 248, in reraise
    raise value.with_traceback(tb)
  File "D:\devuri\workspace\server\venv352\lib\site-packages\sqlalchemy\engine\base.py", line 1193, in _execute_context
    context)
  File "D:\devuri\workspace\server\venv352\lib\site-packages\sqlalchemy\engine\default.py", line 509, in do_execute
    cursor.execute(statement, parameters)
  File "D:\devuri\workspace\server\venv352\lib\site-packages\MySQLdb\cursors.py", line 250, in execute
    self.errorhandler(self, exc, value)
  File "D:\devuri\workspace\server\venv352\lib\site-packages\MySQLdb\connections.py", line 50, in defaulterrorhandler
    raise errorvalue
  File "D:\devuri\workspace\server\venv352\lib\site-packages\MySQLdb\cursors.py", line 247, in execute
    res = self._query(query)
  File "D:\devuri\workspace\server\venv352\lib\site-packages\MySQLdb\cursors.py", line 411, in _query
    rowcount = self._do_query(q)
  File "D:\devuri\workspace\server\venv352\lib\site-packages\MySQLdb\cursors.py", line 374, in _do_query
    db.query(q)
  File "D:\devuri\workspace\server\venv352\lib\site-packages\MySQLdb\connections.py", line 277, in query
    _mysql.connection.query(self, query)
sqlalchemy.exc.OperationalError: (_mysql_exceptions.OperationalError) (1292, "Incorrect date value: '200159' for column 'birthday' at row 1") [SQL: 'INSERT INTO account (user_id, name, birthday, account_type, bot_type) VALUES (%s, %s, %s, %s, %s)'] [parameters: ('test@gmail.com', 'ÇÑÀ¯¸®', '200159', 0, 1)] (Background on this error at: http://sqlalche.me/e/e3q8)
