Exception on /messages/ [POST]
Traceback (most recent call last):
  File "D:\devuri\workspace\server\venv352\lib\site-packages\flask\app.py", line 2292, in wsgi_app
    response = self.full_dispatch_request()
  File "D:\devuri\workspace\server\venv352\lib\site-packages\flask\app.py", line 1815, in full_dispatch_request
    rv = self.handle_user_exception(e)
  File "D:\devuri\workspace\server\venv352\lib\site-packages\flask\app.py", line 1718, in handle_user_exception
    reraise(exc_type, exc_value, tb)
  File "D:\devuri\workspace\server\venv352\lib\site-packages\flask\_compat.py", line 35, in reraise
    raise value
  File "D:\devuri\workspace\server\venv352\lib\site-packages\flask\app.py", line 1813, in full_dispatch_request
    rv = self.dispatch_request()
  File "D:\devuri\workspace\server\venv352\lib\site-packages\flask\app.py", line 1799, in dispatch_request
    return self.view_functions[rule.endpoint](**req.view_args)
  File "D:\devuri\workspace\server\DajeongBot-server\djbot\blueprints\message.py", line 38, in add_messages
    result = reply_message_for_select_review(content, content_message[0])
  File "D:\devuri\workspace\server\DajeongBot-server\djbot\controllers\schedule.py", line 122, in reply_message_for_select_review
    "id": events[0].id,
IndexError: list index out of range
Exception on /messages/ [POST]
Traceback (most recent call last):
  File "D:\devuri\workspace\server\venv352\lib\site-packages\flask\app.py", line 2292, in wsgi_app
    response = self.full_dispatch_request()
  File "D:\devuri\workspace\server\venv352\lib\site-packages\flask\app.py", line 1815, in full_dispatch_request
    rv = self.handle_user_exception(e)
  File "D:\devuri\workspace\server\venv352\lib\site-packages\flask\app.py", line 1718, in handle_user_exception
    reraise(exc_type, exc_value, tb)
  File "D:\devuri\workspace\server\venv352\lib\site-packages\flask\_compat.py", line 35, in reraise
    raise value
  File "D:\devuri\workspace\server\venv352\lib\site-packages\flask\app.py", line 1813, in full_dispatch_request
    rv = self.dispatch_request()
  File "D:\devuri\workspace\server\venv352\lib\site-packages\flask\app.py", line 1799, in dispatch_request
    return self.view_functions[rule.endpoint](**req.view_args)
  File "D:\devuri\workspace\server\DajeongBot-server\djbot\blueprints\message.py", line 34, in add_messages
    result = reply_message(content)
  File "D:\devuri\workspace\server\DajeongBot-server\djbot\controllers\message.py", line 57, in reply_message
    result['message'] = danbee_message[result['message']][content['bot_type']][randint(0, 3)]
KeyError: 'SlotNode_1537357975990'
Exception on /messages/ [POST]
Traceback (most recent call last):
  File "D:\devuri\workspace\server\venv352\lib\site-packages\flask\app.py", line 2292, in wsgi_app
    response = self.full_dispatch_request()
  File "D:\devuri\workspace\server\venv352\lib\site-packages\flask\app.py", line 1815, in full_dispatch_request
    rv = self.handle_user_exception(e)
  File "D:\devuri\workspace\server\venv352\lib\site-packages\flask\app.py", line 1718, in handle_user_exception
    reraise(exc_type, exc_value, tb)
  File "D:\devuri\workspace\server\venv352\lib\site-packages\flask\_compat.py", line 35, in reraise
    raise value
  File "D:\devuri\workspace\server\venv352\lib\site-packages\flask\app.py", line 1813, in full_dispatch_request
    rv = self.dispatch_request()
  File "D:\devuri\workspace\server\venv352\lib\site-packages\flask\app.py", line 1799, in dispatch_request
    return self.view_functions[rule.endpoint](**req.view_args)
  File "D:\devuri\workspace\server\DajeongBot-server\djbot\blueprints\message.py", line 34, in add_messages
    result = reply_message(content,content['chat_type'] )
  File "D:\devuri\workspace\server\DajeongBot-server\djbot\controllers\message.py", line 76, in reply_message
    update_event(reply)
  File "D:\devuri\workspace\server\DajeongBot-server\djbot\controllers\schedule.py", line 40, in update_event
    event.schedule_when = current + datetime.timedelta(days=int(param['schedule_when']))
ValueError: invalid literal for int() with base 10: ''
Exception on /messages/ [POST]
Traceback (most recent call last):
  File "D:\devuri\workspace\server\venv352\lib\site-packages\flask\app.py", line 2292, in wsgi_app
    response = self.full_dispatch_request()
  File "D:\devuri\workspace\server\venv352\lib\site-packages\flask\app.py", line 1815, in full_dispatch_request
    rv = self.handle_user_exception(e)
  File "D:\devuri\workspace\server\venv352\lib\site-packages\flask\app.py", line 1718, in handle_user_exception
    reraise(exc_type, exc_value, tb)
  File "D:\devuri\workspace\server\venv352\lib\site-packages\flask\_compat.py", line 35, in reraise
    raise value
  File "D:\devuri\workspace\server\venv352\lib\site-packages\flask\app.py", line 1813, in full_dispatch_request
    rv = self.dispatch_request()
  File "D:\devuri\workspace\server\venv352\lib\site-packages\flask\app.py", line 1799, in dispatch_request
    return self.view_functions[rule.endpoint](**req.view_args)
  File "D:\devuri\workspace\server\DajeongBot-server\djbot\blueprints\message.py", line 34, in add_messages
    result = reply_message(content,content['chat_type'] )
  File "D:\devuri\workspace\server\DajeongBot-server\djbot\controllers\message.py", line 92, in reply_message
    print(result_json)
UnicodeEncodeError: 'cp949' codec can't encode character '\u11a2' in position 118: illegal multibyte sequence
Exception on /notifications [GET]
Traceback (most recent call last):
  File "D:\devuri\workspace\server\venv352\lib\site-packages\flask\app.py", line 2292, in wsgi_app
    response = self.full_dispatch_request()
  File "D:\devuri\workspace\server\venv352\lib\site-packages\flask\app.py", line 1815, in full_dispatch_request
    rv = self.handle_user_exception(e)
  File "D:\devuri\workspace\server\venv352\lib\site-packages\flask\app.py", line 1718, in handle_user_exception
    reraise(exc_type, exc_value, tb)
  File "D:\devuri\workspace\server\venv352\lib\site-packages\flask\_compat.py", line 35, in reraise
    raise value
  File "D:\devuri\workspace\server\venv352\lib\site-packages\flask\app.py", line 1813, in full_dispatch_request
    rv = self.dispatch_request()
  File "D:\devuri\workspace\server\venv352\lib\site-packages\flask\app.py", line 1799, in dispatch_request
    return self.view_functions[rule.endpoint](**req.view_args)
  File "D:\devuri\workspace\server\DajeongBot-server\djbot\blueprints\test.py", line 91, in notification
    contents = convert_notification_message(event, account.bot_type, randint(0, 3))
UnboundLocalError: local variable 'account' referenced before assignment
Exception on /messages/ [POST]
Traceback (most recent call last):
  File "D:\devuri\workspace\server\venv352\lib\site-packages\flask\app.py", line 2292, in wsgi_app
    response = self.full_dispatch_request()
  File "D:\devuri\workspace\server\venv352\lib\site-packages\flask\app.py", line 1815, in full_dispatch_request
    rv = self.handle_user_exception(e)
  File "D:\devuri\workspace\server\venv352\lib\site-packages\flask\app.py", line 1718, in handle_user_exception
    reraise(exc_type, exc_value, tb)
  File "D:\devuri\workspace\server\venv352\lib\site-packages\flask\_compat.py", line 35, in reraise
    raise value
  File "D:\devuri\workspace\server\venv352\lib\site-packages\flask\app.py", line 1813, in full_dispatch_request
    rv = self.dispatch_request()
  File "D:\devuri\workspace\server\venv352\lib\site-packages\flask\app.py", line 1799, in dispatch_request
    return self.view_functions[rule.endpoint](**req.view_args)
  File "D:\devuri\workspace\server\DajeongBot-server\djbot\blueprints\message.py", line 34, in add_messages
    result = reply_message(content,content['chat_type'] )
  File "D:\devuri\workspace\server\DajeongBot-server\djbot\controllers\message.py", line 90, in reply_message
    chat = Chat(account_id=content['account_id'], content=result['message'], node_type=NODE_TYPE[node_type],
KeyError: 4
Exception on /fcm [GET]
Traceback (most recent call last):
  File "D:\devuri\workspace\server\venv352\lib\site-packages\flask\app.py", line 2292, in wsgi_app
    response = self.full_dispatch_request()
  File "D:\devuri\workspace\server\venv352\lib\site-packages\flask\app.py", line 1815, in full_dispatch_request
    rv = self.handle_user_exception(e)
  File "D:\devuri\workspace\server\venv352\lib\site-packages\flask\app.py", line 1718, in handle_user_exception
    reraise(exc_type, exc_value, tb)
  File "D:\devuri\workspace\server\venv352\lib\site-packages\flask\_compat.py", line 35, in reraise
    raise value
  File "D:\devuri\workspace\server\venv352\lib\site-packages\flask\app.py", line 1813, in full_dispatch_request
    rv = self.dispatch_request()
  File "D:\devuri\workspace\server\venv352\lib\site-packages\flask\app.py", line 1799, in dispatch_request
    return self.view_functions[rule.endpoint](**req.view_args)
  File "D:\devuri\workspace\server\DajeongBot-server\djbot\blueprints\test.py", line 218, in test_fcm
    push_service.notify_single_device(registration_id=token.token, data_message=param, content_available=True)
AttributeError: 'str' object has no attribute 'token'
